Workbook
Name IQ_CH: 110000
Name IQ_CQ: 5000
Name IQ_CY: 10000
Name IQ_DAILY: 500000
Name IQ_FH: 100000
Name IQ_FQ: 500
Name IQ_FY: 1000
Name IQ_LTM: 2000
Name IQ_MONTH: 15000
Name IQ_NTM: 6000
Name IQ_WEEK: 50000
Name IQ_YTD: 3000

Sheet Cover

Sheet Input Sheet
B3: Please provide the below inputs
B5: Name of the Company | C5: Epigral Ltd.
B8: Wacc Inputs
B9: Country | C9: India
B10: Local Currency 10Y Government Bond | C10: 0.067
B11: =C9&"'s"&" Moody's Soverign Rating " -> India's Moody's Soverign Rating | C11: =VLOOKUP(C9,'Damodaran Data'!B4:D161,3,) -> Baa3
B12: Credit default spread as per Dr Damodaran | C12: =VLOOKUP(C9,'Damodaran Data'!B4:E161,4,) -> 0.021609858
B13: Implied US Equity Risk Premium | C13: 0.0418
B14: Asset Beta | C14: 1.02
B15: Asset Beta Variation (+/-) | C15: 0.15
B16: Debt to Eauity Ratio | C16: ='Assumptions Working'!$H$885 -> 0.26207983
B17: Debt to Capital (Gearing) | C17: ='Assumptions Working'!$H$886 -> 0.2076571
B18: Marginal Tax Rate | C18: 0.2517
B19: Company Credit Rating Available | C19: No
B20: Company is Small or Large Firm ? | C20: L | G20: L | H20: Yes
B21: Provide Credit Rating | C21: A1/A+ | G21: S | H21: No
B22: Interest Coverage Ratio | C22: ='3 Statement Model'!H31/'3 Statement Model'!H35 -> 10.921509
B23: ICR Based Corporate Default Spread | C23: =IF(C20="L",VLOOKUP(C22,'Damodaran Data'!G6:J21,4,TRUE),VLOOKUP(C22,'Damodaran Data'!L6:O21,4,TRUE)) -> 0.004
B24: Small Size Premium | C24: 0.1222
B25: Assets Specific Risk Premium | C25: 0

Sheet Valuation Summary
B1: Valuation Summary
A4: # | B4: Valuation Methods | C4: Enterprise Value | D4: Equity Value Available for Equity Shareholders | E4: Value Per Share | F4: Market Price | G4: Discount/ Premium | H4: Discount/ Premium % | I4: Interpretaion
B6: Discounted Cash Flow - Perpetuity Growth | C6: 4587.7173 | D6: 4186.6783 | E6: 971.38708 | F6: 884 | G6: =E6-F6 -> 87.387081 | H6: =G6/F6 -> 0.098854164 | I6: Slight undervaluation
B7: Discounted Cash Flow - Exit Multiple | C7: 9089.6091 | D7: 8688.5701 | E7: 2015.9095 | F7: 884 | G7: =E7-F7 -> 1131.9095 | H7: =G7/F7 -> 1.2804407 | I7: Very undervalued
B8: Relative Valuation - EV/EBITDA | C8: 7064.0054 | D8: 6662.9664 | E8: 1545.9319 | F8: 884 | G8: =E8-F8 -> 661.93188 | H8: =G8/F8 -> 0.74879172 | I8: Undervalued
B9: Relative Valuation - EV/Sales | C9: 2307.7093 | D9: 1906.6703 | E9: 442.3829 | F9: 884 | G9: =E9-F9 -> -441.6171 | H9: =G9/F9 -> -0.49956685 | I9: Overvalued
B10: Relative Valuation - Price/Earnings | C10: 13122.327 | D10: 12721.288 | E10: 2951.575 | F10: 884 | G10: =E10-F10 -> 2067.575 | H10: =G10/F10 -> 2.3388858 | I10: Very undervalued

Sheet Beta Calculation
B2: Peers Calculations | C2: 2 Years Weekly Equity Beta | D2: 2 Years Avg D/E | E2: 2 Years avg D/(D+E) | F2: 2 Yearly Asset Beta | H2: 5 Years MonthLy Equity Beta | I2: 5 Years Avg D/E | J2: 5 Years avg D/(D+E) | K2: 5 Yearly Asset Beta
B3: Gujarat Alkalies & Chemicals Ltd (GAKL) | C3: =I209 -> 1.160871 | D3: =H90 -> 0.049479626 | E3: =H92 -> 0.045024077 | F3: =C3/(1+(1-$M$3)*D3) -> 1.1194237 | H3: =I79 -> 1.5204461 | I3: =H94 -> 0.077913959 | J3: =H95 -> 0.070993764 | K3: =H3/(1+(1-$M$3)*I3) -> 1.4366831 | M3: 0.2517
B4: Gujarat Narmada Valley Fertilizers & Chemicals Ltd (GNFC) | C4: =M209 -> 1.3114087 | D4: =N90 -> 0.0063605645 | E4: =N92 -> 0.0062850462 | F4: =C4/(1+(1-$M$3)*D4) -> 1.3051965 | H4: =M79 -> 1.2939189 | I4: =N94 -> 0.0027700594 | J4: =N95 -> 0.0027397431 | K4: =H4/(1+(1-$M$3)*I4) -> 1.2912424
B5: Grasim Industries Ltd | C5: =Q209 -> 1.2088705 | D5: =T90 -> 1.7289794 | E5: =T92 -> 0.6319277 | F5: =C5/(1+(1-$M$3)*D5) -> 0.52701761 | H5: =Q79 -> 1.1622769 | I5: =T94 -> 1.3922632 | J5: =T95 -> 0.57489838 | K5: =H5/(1+(1-$M$3)*I5) -> 0.56923278
B6: Chemplast Sanmar Ltd | C6: =U209 -> 1.202175 | D6: =Z90 -> 0.90038429 | E6: =Z92 -> 0.47377702 | F6: =C6/(1+(1-$M$3)*D6) -> 0.71824921 | H6: =U79 -> 1.0602292 | I6: =Z94 -> 0.57330196 | J6: =Z95 -> 0.56792781 | K6: =H6/(1+(1-$M$3)*I6) -> 0.74193691
B7: SRF | C7: =Y209 -> 0.80010021 | D7: =AF90 -> 0.40629279 | E7: =AF92 -> 0.28854247 | F7: =C7/(1+(1-$M$3)*D7) -> 0.61356018 | H7: =Y79 -> 0.95707112 | I7: =AF94 -> 0.43578461 | J7: =AF95 -> 0.30292616 | K7: =H7/(1+(1-$M$3)*I7) -> 0.72171996
B8: TGV SRACC LTD | C8: =AC209 -> 1.3395297 | D8: =AL90 -> 0.29796962 | E8: =AL92 -> 0.22955411 | F8: =C8/(1+(1-$M$3)*D8) -> 1.0953081 | H8: =AC79 -> 0.71612139 | I8: =AL94 -> 0.4516278 | J8: =AL95 -> 0.2949532 | K8: =H8/(1+(1-$M$3)*I8) -> 0.53523655
B9: Primo Chemicals | C9: =AG209 -> 0.71670229 | D9: =AR90 -> 0.44664083 | E9: =AR92 -> 0.30868491 | F9: =C9/(1+(1-$M$3)*D9) -> 0.53716896 | H9: =AG79 -> 0.34179507 | I9: =AR94 -> 0.29530943 | J9: =AR95 -> 0.21378119 | K9: =H9/(1+(1-$M$3)*I9) -> 0.27993502
B10: Deepak Nitrite | C10: =AK209 -> 1.0388116 | D10: =AX90 -> 0.14739261 | E10: =AX92 -> 0.12333011 | F10: =C10/(1+(1-$M$3)*D10) -> 0.93561856 | H10: =AK79 -> 1.5441467 | I10: =AX94 -> 0.13169868 | J10: =AX95 -> 0.11027597 | K10: =H10/(1+(1-$M$3)*I10) -> 1.4056224
B11: EPIGRAL | C11: =AO209 -> 1.6715682 | D11: =BD90 -> 0.53978853 | E11: =BD92 -> 0.33595745 | F11: =C11/(1+(1-$M$3)*D11) -> 1.1906403 | H11: =AO79 -> 1.5680078 | I11: =BD94 -> 0.97148972 | J11: =BD95 -> 0.46285376 | K11: =H11/(1+(1-$M$3)*I11) -> 0.90795533
D13: x | E13: Nifty
B14: Calculations 5 Yearly Monthly | D14: Y | E14: All
B16: Nifty 50 Index | C16: Nifty 50 Index | G16: Gujarat Alkalies & Chemicals Ltd (GAKL) | K16: Gujarat Narmada Valley Fertilizers & Chemicals Ltd (GNFC) | O16: Grasim Industries Ltd | S16: Chemplast
C17: Date | D17: Price | E17: Nifty 50 Returns | G17: Date | H17: Price | I17: GAKL | K17: Date | L17: Price | M17: GNFC | O17: Date | P17: Price | Q17: Grasim | S17: Date | T17: Price | U17: Chemplast | W17: Date | X17: Price | Y17: SRFL | AA17: Date | AB17: Price | AC17: TGVS | AE17: Date | AF17: Price | AG17: Primo | AI17: Date | AJ17: Price | AK17: DPNT | AM17: Date | AN17: Price | AO17: Epigral
C18: 46054 | D18: 24964.55 | G18: 46054 | H18: 439.5 | K18: 46054 | L18: 464.4 | O18: 46054 | P18: 2758.2 | S18: 46054 | T18: 249.35 | W18: 46054 | X18: 2771.5 | AA18: 46054 | AB18: 85.09 | AE18: 46054 | AF18: 19.8 | AI18: 46054 | AJ18: 1604.5 | AM18: 46054 | AN18: 922.8
C19: 46023 | D19: 25320.65 | E19: =D19/D18-1 -> 0.014264227 | G19: 46023 | H19: 455.95 | I19: =H19/H18-1 -> 0.037428896 | K19: 46023 | L19: 466.8 | M19: =L19/L18-1 -> 0.0051679587 | O19: 46023 | P19: 2819 | Q19: =P19/P18-1 -> 0.022043362 | S19: 46023 | T19: 260.25 | U19: =T19/T18-1 -> 0.043713656 | W19: 46023 | X19: 2816.3 | Y19: =X19/X18-1 -> 0.016164532 | AA19: 46023 | AB19: 87.2 | AC19: =AB19/AB18-1 -> 0.024797273 | AE19: 46023 | AF19: 20.14 | AG19: =AF19/AF18-1 -> 0.017171717 | AI19: 46023 | AJ19: 1642.5 | AK19: =AJ19/AJ18-1 -> 0.02368339 | AM19: 46023 | AN19: 1043.1 | AO19: =AN19/AN18-1 -> 0.13036411
C20: 45992 | D20: 26129.6 | E20: =D20/D19-1 -> 0.031948232 | G20: 45992 | H20: 504.25 | I20: =H20/H19-1 -> 0.10593267 | K20: 45992 | L20: 493.75 | M20: =L20/L19-1 -> 0.057733505 | O20: 45992 | P20: 2829 | Q20: =P20/P19-1 -> 0.0035473572 | S20: 45992 | T20: 261.2 | U20: =T20/T19-1 -> 0.0036503362 | W20: 45992 | X20: 3075 | Y20: =X20/X19-1 -> 0.091858112 | AA20: 45992 | AB20: 111.4 | AC20: =AB20/AB19-1 -> 0.27752294 | AE20: 45992 | AF20: 23.95 | AG20: =AF20/AF19-1 -> 0.18917577 | AI20: 45992 | AJ20: 1731.7 | AK20: =AJ20/AJ19-1 -> 0.054307458 | AM20: 45992 | AN20: 1220.1 | AO20: =AN20/AN19-1 -> 0.16968651
C21: 45962 | D21: 26202.95 | E21: =D21/D20-1 -> 0.0028071612 | G21: 45962 | H21: 530.5 | I21: =H21/H20-1 -> 0.052057511 | K21: 45962 | L21: 497.95 | M21: =L21/L20-1 -> 0.0085063291 | O21: 45962 | P21: 2739.4 | Q21: =P21/P20-1 -> -0.031671969 | S21: 45962 | T21: 284.2 | U21: =T21/T20-1 -> 0.08805513 | W21: 45962 | X21: 2927.3 | Y21: =X21/X20-1 -> -0.04803252 | AA21: 45962 | AB21: 114.15 | AC21: =AB21/AB20-1 -> 0.024685817 | AE21: 45962 | AF21: 25.52 | AG21: =AF21/AF20-1 -> 0.065553236 | AI21: 45962 | AJ21: 1558.6 | AK21: =AJ21/AJ20-1 -> -0.099959577 | AM21: 45962 | AN21: 1511.7 | AO21: =AN21/AN20-1 -> 0.2389968
C22: 45931 | D22: 25722.1 | E22: =D22/D21-1 -> -0.018350987 | G22: 45931 | H22: 572.05 | I22: =H22/H21-1 -> 0.078322337 | K22: 45931 | L22: 502.95 | M22: =L22/L21-1 -> 0.010041169 | O22: 45931 | P22: 2891.7 | Q22: =P22/P21-1 -> 0.055596116 | S22: 45931 | T22: 398.85 | U22: =T22/T21-1 -> 0.40341309 | W22: 45931 | X22: 2930.5 | Y22: =X22/X21-1 -> 0.0010931575 | AA22: 45931 | AB22: 120.55 | AC22: =AB22/AB21-1 -> 0.056066579 | AE22: 45931 | AF22: 23.55 | AG22: =AF22/AF21-1 -> -0.077194357 | AI22: 45931 | AJ22: 1728.4 | AK22: =AJ22/AJ21-1 -> 0.10894392 | AM22: 45931 | AN22: 1689.7 | AO22: =AN22/AN21-1 -> 0.11774823
C23: 45901 | D23: 24611.1 | E23: =D23/D22-1 -> -0.04319243 | G23: 45901 | H23: 546.55 | I23: =H23/H22-1 -> -0.044576523 | K23: 45901 | L23: 491 | M23: =L23/L22-1 -> -0.023759817 | O23: 45901 | P23: 2756.9 | Q23: =P23/P22-1 -> -0.046616177 | S23: 45901 | T23: 388.9 | U23: =T23/T22-1 -> -0.024946722 | W23: 45901 | X23: 2823.6 | Y23: =X23/X22-1 -> -0.036478417 | AA23: 45901 | AB23: 119.05 | AC23: =AB23/AB22-1 -> -0.01244297 | AE23: 45901 | AF23: 23.76 | AG23: =AF23/AF22-1 -> 0.0089171975 | AI23: 45901 | AJ23: 1835.1 | AK23: =AJ23/AJ22-1 -> 0.061733395 | AM23: 45901 | AN23: 1691.1 | AO23: =AN23/AN22-1 -> 0.00082854945
C24: 45870 | D24: 24426.85 | E24: =D24/D23-1 -> -0.0074864594 | G24: 45870 | H24: 564.3 | I24: =H24/H23-1 -> 0.032476443 | K24: 45870 | L24: 522.75 | M24: =L24/L23-1 -> 0.064663951 | O24: 45870 | P24: 2775.6 | Q24: =P24/P23-1 -> 0.0067829809 | S24: 45870 | T24: 427.3 | U24: =T24/T23-1 -> 0.098740036 | W24: 45870 | X24: 2836.4 | Y24: =X24/X23-1 -> 0.00453322 | AA24: 45870 | AB24: 125.6 | AC24: =AB24/AB23-1 -> 0.0550189 | AE24: 45870 | AF24: 25.67 | AG24: =AF24/AF23-1 -> 0.080387205 | AI24: 45870 | AJ24: 1787.9 | AK24: =AJ24/AJ23-1 -> -0.025720669 | AM24: 45870 | AN24: 1811.4 | AO24: =AN24/AN23-1 -> 0.07113713
C25: 45839 | D25: 24768.35 | E25: =D25/D24-1 -> 0.013980517 | G25: 45839 | H25: 581.6 | I25: =H25/H24-1 -> 0.030657452 | K25: 45839 | L25: 540.8 | M25: =L25/L24-1 -> 0.034528934 | O25: 45839 | P25: 2746.4 | Q25: =P25/P24-1 -> -0.010520248 | S25: 45839 | T25: 416.85 | U25: =T25/T24-1 -> -0.024455886 | W25: 45839 | X25: 3040.8 | Y25: =X25/X24-1 -> 0.072063179 | AA25: 45839 | AB25: 115.43 | AC25: =AB25/AB24-1 -> -0.080971338 | AE25: 45839 | AF25: 28.06 | AG25: =AF25/AF24-1 -> 0.093104792 | AI25: 45839 | AJ25: 1840.4 | AK25: =AJ25/AJ24-1 -> 0.029364058 | AM25: 45839 | AN25: 2019.2 | AO25: =AN25/AN24-1 -> 0.1147179
C26: 45809 | D26: 25517.05 | E26: =D26/D25-1 -> 0.030228094 | G26: 45809 | H26: 599.65 | I26: =H26/H25-1 -> 0.031035076 | K26: 45809 | L26: 553 | M26: =L26/L25-1 -> 0.022559172 | O26: 45809 | P26: 2844.5 | Q26: =P26/P25-1 -> 0.035719487 | S26: 45809 | T26: 439.05 | U26: =T26/T25-1 -> 0.053256567 | W26: 45809 | X26: 3242.1 | Y26: =X26/X25-1 -> 0.066199684 | AA26: 45809 | AB26: 98.25 | AC26: =AB26/AB25-1 -> -0.14883479 | AE26: 45809 | AF26: 25.81 | AG26: =AF26/AF25-1 -> -0.080185317 | AI26: 45809 | AJ26: 1987.1 | AK26: =AJ26/AJ25-1 -> 0.079710932 | AM26: 45809 | AN26: 1808.2 | AO26: =AN26/AN25-1 -> -0.10449683
C27: 45778 | D27: 24750.7 | E27: =D27/D26-1 -> -0.03003286 | G27: 45778 | H27: 574 | I27: =H27/H26-1 -> -0.042774952 | K27: 45778 | L27: 535.45 | M27: =L27/L26-1 -> -0.031735986 | O27: 45778 | P27: 2545.8 | Q27: =P27/P26-1 -> -0.10500967 | S27: 45778 | T27: 424.45 | U27: =T27/T26-1 -> -0.033253616 | W27: 45778 | X27: 2861 | Y27: =X27/X26-1 -> -0.11754727 | AA27: 45778 | AB27: 100.6 | AC27: =AB27/AB26-1 -> 0.023918575 | AE27: 45778 | AF27: 25.99 | AG27: =AF27/AF26-1 -> 0.0069740411 | AI27: 45778 | AJ27: 2027.3 | AK27: =AJ27/AJ26-1 -> 0.020230487 | AM27: 45778 | AN27: 1780.1 | AO27: =AN27/AN26-1 -> -0.015540316
C28: 45748 | D28: 24334.2 | E28: =D28/D27-1 -> -0.016827807 | G28: 45748 | H28: 605.7 | I28: =H28/H27-1 -> 0.055226481 | K28: 45748 | L28: 486.35 | M28: =L28/L27-1 -> -0.091698571 | O28: 45748 | P28: 2737.5 | Q28: =P28/P27-1 -> 0.075300495 | S28: 45748 | T28: 410.65 | U28: =T28/T27-1 -> -0.032512663 | W28: 45748 | X28: 3008.9 | Y28: =X28/X27-1 -> 0.051695211 | AA28: 45748 | AB28: 98.93 | AC28: =AB28/AB27-1 -> -0.016600398 | AE28: 45748 | AF28: 25.87 | AG28: =AF28/AF27-1 -> -0.0046171604 | AI28: 45748 | AJ28: 1935.6 | AK28: =AJ28/AJ27-1 -> -0.045232575 | AM28: 45748 | AN28: 1735.2 | AO28: =AN28/AN27-1 -> -0.025223302
C29: 45717 | D29: 23519.35 | E29: =D29/D28-1 -> -0.033485794 | G29: 45717 | H29: 579.2 | I29: =H29/H28-1 -> -0.043751032 | K29: 45717 | L29: 496.45 | M29: =L29/L28-1 -> 0.020766937 | O29: 45717 | P29: 2611.15 | Q29: =P29/P28-1 -> -0.046155251 | S29: 45717 | T29: 435.05 | U29: =T29/T28-1 -> 0.059417996 | W29: 45717 | X29: 2939.15 | Y29: =X29/X28-1 -> -0.023181229 | AA29: 45717 | AB29: 94.9 | AC29: =AB29/AB28-1 -> -0.040735874 | AE29: 45717 | AF29: 21.19 | AG29: =AF29/AF28-1 -> -0.18090452 | AI29: 45717 | AJ29: 1983.6 | AK29: =AJ29/AJ28-1 -> 0.024798512 | AM29: 45717 | AN29: 1904.1 | AO29: =AN29/AN28-1 -> 0.097337483
C30: 45689 | D30: 22124.7 | E30: =D30/D29-1 -> -0.059297982 | G30: 45689 | H30: 524.15 | I30: =H30/H29-1 -> -0.09504489 | K30: 45689 | L30: 468.85 | M30: =L30/L29-1 -> -0.055594723 | O30: 45689 | P30: 2306.65 | Q30: =P30/P29-1 -> -0.11661528 | S30: 45689 | T30: 404.6 | U30: =T30/T29-1 -> -0.069991955 | W30: 45689 | X30: 2795.4 | Y30: =X30/X29-1 -> -0.048908698 | AA30: 45689 | AB30: 91.82 | AC30: =AB30/AB29-1 -> -0.032455216 | AE30: 45689 | AF30: 26.14 | AG30: =AF30/AF29-1 -> 0.23360076 | AI30: 45689 | AJ30: 1851.3 | AK30: =AJ30/AJ29-1 -> -0.066696915 | AM30: 45689 | AN30: 1613.35 | AO30: =AN30/AN29-1 -> -0.15269681
... C71: 44440 | D71: 17618.15 | E71: =D71/D70-1 -> -0.0030274479 | G71: 44440 | H71: 672.75 | I71: =H71/H70-1 -> -0.1038961 | K71: 44440 | L71: 434.25 | M71: =L71/L70-1 -> -0.05720799 | O71: 44440 | P71: 1657.68 | Q71: =P71/P70-1 -> -0.030006554 | S71: 44440 | T71: 612.45 | U71: =T71/T70-1 -> -0.05863818 | W71: 44440 | X71: 2255.82 | Y71: =X71/X70-1 -> 0.065422944 | AA71: 44440 | AB71: 55.45 | AC71: =AB71/AB70-1 -> 0.0081818182 | AE71: 44440 | AF71: 26.02 | AG71: =AF71/AF70-1 -> -0.21814904 | AI71: 44440 | AJ71: 2406.55 | AK71: =AJ71/AJ70-1 -> 0.079001054 | AM71: 44440 | AN71: 778.2 | AO71: =AN71/AN70-1 -> -0.12236382
C72: 44409 | D72: 17132.2 | E72: =D72/D71-1 -> -0.027582351 | G72: 44409 | H72: 454.5 | I72: =H72/H71-1 -> -0.32441472 | K72: 44409 | L72: 332.6 | M72: =L72/L71-1 -> -0.23408175 | O72: 44409 | P72: 1489.82 | Q72: =P72/P71-1 -> -0.101262 | W72: 44409 | X72: 2027.95 | Y72: =X72/X71-1 -> -0.10101427 | AA72: 44409 | AB72: 34.6 | AC72: =AB72/AB71-1 -> -0.37601443 | AE72: 44409 | AF72: 22.72 | AG72: =AF72/AF71-1 -> -0.12682552 | AI72: 44409 | AJ72: 2283.6 | AK72: =AJ72/AJ71-1 -> -0.051089734
C73: 44378 | D73: 15763.05 | E73: =D73/D72-1 -> -0.079916765 | G73: 44378 | H73: 478.6 | I73: =H73/H72-1 -> 0.053025303 | K73: 44378 | L73: 384.7 | M73: =L73/L72-1 -> 0.15664462 | O73: 44378 | P73: 1536.31 | Q73: =P73/P72-1 -> 0.031205112 | W73: 44378 | X73: 1731.74 | Y73: =X73/X72-1 -> -0.14606376 | AA73: 44378 | AB73: 39.85 | AC73: =AB73/AB72-1 -> 0.1517341 | AE73: 44378 | AF73: 24.85 | AG73: =AF73/AF72-1 -> 0.09375 | AI73: 44378 | AJ73: 2039.2 | AK73: =AJ73/AJ72-1 -> -0.107024
C74: 44348 | D74: 15721.5 | E74: =D74/D73-1 -> -0.0026359112 | G74: 44348 | H74: 402.3 | I74: =H74/H73-1 -> -0.15942332 | K74: 44348 | L74: 377.2 | M74: =L74/L73-1 -> -0.019495711 | O74: 44348 | P74: 1484.22 | Q74: =P74/P73-1 -> -0.033905917 | W74: 44348 | X74: 1455.14 | Y74: =X74/X73-1 -> -0.15972375 | AA74: 44348 | AB74: 30.15 | AC74: =AB74/AB73-1 -> -0.2434128 | AE74: 44348 | AF74: 16.43 | AG74: =AF74/AF73-1 -> -0.338833 | AI74: 44348 | AJ74: 1807.63 | AK74: =AJ74/AJ73-1 -> -0.11355924
C75: 44317 | D75: 15582.8 | E75: =D75/D74-1 -> -0.0088223134 | G75: 44317 | H75: 402.45 | I75: =H75/H74-1 -> 0.00037285608 | K75: 44317 | L75: 375.85 | M75: =L75/L74-1 -> -0.0035790032 | O75: 44317 | P75: 1456.94 | Q75: =P75/P74-1 -> -0.018380025 | W75: 44317 | X75: 1302.63 | Y75: =X75/X74-1 -> -0.10480778 | AA75: 44317 | AB75: 34.7 | AC75: =AB75/AB74-1 -> 0.15091211 | AE75: 44317 | AF75: 17.57 | AG75: =AF75/AF74-1 -> 0.069385271 | AI75: 44317 | AJ75: 1784.49 | AK75: =AJ75/AJ74-1 -> -0.012801292
C76: 44287 | D76: 14631.1 | E76: =D76/D75-1 -> -0.061073748 | G76: 44287 | H76: 412.15 | I76: =H76/H75-1 -> 0.024102373 | K76: 44287 | L76: 361.85 | M76: =L76/L75-1 -> -0.037248902 | O76: 44287 | P76: 1388.16 | Q76: =P76/P75-1 -> -0.047208533 | W76: 44287 | X76: 1286.22 | Y76: =X76/X75-1 -> -0.012597591 | AA76: 44287 | AB76: 32.95 | AC76: =AB76/AB75-1 -> -0.050432277 | AE76: 44287 | AF76: 17.43 | AG76: =AF76/AF75-1 -> -0.0079681275 | AI76: 44287 | AJ76: 1864.65 | AK76: =AJ76/AJ75-1 -> 0.044920397
C77: 44256 | D77: 14690.7 | E77: =D77/D76-1 -> 0.0040735146 | G77: 44256 | H77: 344.8 | I77: =H77/H76-1 -> -0.16341138 | K77: 44256 | L77: 300.2 | M77: =L77/L76-1 -> -0.17037446 | O77: 44256 | P77: 1436.49 | Q77: =P77/P76-1 -> 0.034815871 | W77: 44256 | X77: 1082.16 | Y77: =X77/X76-1 -> -0.15865093 | AA77: 44256 | AB77: 24.25 | AC77: =AB77/AB76-1 -> -0.26403642 | AE77: 44256 | AF77: 17.85 | AG77: =AF77/AF76-1 -> 0.024096386 | AI77: 44256 | AJ77: 1655.65 | AK77: =AJ77/AJ76-1 -> -0.11208538
H79: Beta | I79: =SLOPE(I19:I77,$E$19:$E$77) -> 1.5204461 | M79: =SLOPE(M19:M77,$E$19:$E$77) -> 1.2939189 | Q79: =SLOPE(Q19:Q77,$E$19:$E$77) -> 1.1622769 | U79: =SLOPE(U19:U71,$E$19:$E$71) -> 1.0602292 | Y79: =SLOPE(Y19:Y77,$E$19:$E$77) -> 0.95707112 | AC79: =SLOPE(AC19:AC77,$E$19:$E$77) -> 0.71612139 | AG79: =SLOPE(AG19:AG77,$E$19:$E$77) -> 0.34179507 | AK79: =SLOPE(AK19:AK77,$E$19:$E$77) -> 1.5441467 | AO79: =SLOPE(AO19:AO71,$E$19:$E$71) -> 1.5680078
D83: GUCL | J83: GNFC | P83: Grasim | V83: Chemplast | AB83: SRF | AH83: TGV | AN83: Primo | AT83: Deepak Nitrite Ltd | AZ83: Epigral
D84: 2021 | E84: =D84+1 -> 2022 | F84: =E84+1 -> 2023 | G84: =F84+1 -> 2024 | H84: =G84+1 -> 2025 | J84: 2021 | K84: =J84+1 -> 2022 | L84: =K84+1 -> 2023 | M84: 2024 | N84: 2025 | P84: 2021 | Q84: =P84+1 -> 2022 | R84: =Q84+1 -> 2023 | S84: 2024 | T84: 2025 | V84: 2021 | W84: =V84+1 -> 2022 | X84: =W84+1 -> 2023 | Y84: 2024 | Z84: 2025 | AB84: 2021 | AC84: =AB84+1 -> 2022 | AD84: =AC84+1 -> 2023 | AE84: 2024 | AF84: 2025 | AH84: 2021 | AI84: =AH84+1 -> 2022 | AJ84: =AI84+1 -> 2023 | AK84: 2024 | AL84: 2025 | AN84: 2021 | AO84: =AN84+1 -> 2022 | AP84: =AO84+1 -> 2023 | AQ84: 2024 | AR84: 2025 | AT84: 2021 | AU84: =AT84+1 -> 2022 | AV84: =AU84+1 -> 2023 | AW84: 2024 | AX84: 2025 | AZ84: 2021 | BA84: =AZ84+1 -> 2022 | BB84: =BA84+1 -> 2023 | BC84: 2024 | BD84: 2025
B85: Debt | D85: 498 | E85: 594 | F85: 597 | H85: 561 | J85: 4 | K85: 2 | L85: 2 | M85: 3 | N85: 106 | P85: 79078 | Q85: 74744 | R85: 103039 | S85: 137155 | T85: 186326 | V85: 2127 | W85: 882 | X85: 1019 | Y85: 1548 | Z85: 1842 | AB85: 3469 | AC85: 3655 | AD85: 4478 | AE85: 5031 | AF85: 4726 | AH85: 499 | AI85: 461 | AJ85: 234 | AK85: 321 | AL85: 357 | AN85: 1 | AO85: 61 | AP85: 145 | AQ85: 178 | AR85: 169 | AT85: 590 | AU85: 315 | AV85: 73 | AW85: 286 | AX85: 1267 | AZ85: 753 | BA85: 993 | BB85: 879 | BC85: 964 | BD85: 593
B86: Total Equity | D86: =SUM(D87:D88) -> 5374 | E86: =SUM(E87:E88) -> 5899 | F86: =SUM(F87:F88) -> 6139 | G86: =SUM(G87:G88) -> 6075 | H86: =SUM(H87:H88) -> 5669 | J86: =SUM(J87:J88) -> 6068 | K86: =SUM(K87:K88) -> 7990 | L86: =SUM(L87:L88) -> 9105 | M86: =SUM(M87:M88) -> 8309 | N86: =SUM(N87:N88) -> 8576 | P86: =SUM(P87:P88) -> 65494 | Q86: =SUM(Q87:Q88) -> 75699 | R86: =SUM(R87:R88) -> 78742 | S86: =SUM(S87:S88) -> 88653 | T86: =SUM(T87:T88) -> 97509 | V86: =SUM(V87:V88) -> -350 | W86: =SUM(W87:W88) -> 1705 | X86: =SUM(X87:X88) -> 1858 | Y86: =SUM(Y87:Y88) -> 1701 | Z86: =SUM(Z87:Z88) -> 2068 | AB86: =SUM(AB87:AB88) -> 6856 | AC86: =SUM(AC87:AC88) -> 8565 | AD86: =SUM(AD87:AD88) -> 10327 | AE86: =SUM(AE87:AE88) -> 11479 | AF86: =SUM(AF87:AF88) -> 12626 | AH86: =SUM(AH87:AH88) -> 610 | AI86: =SUM(AI87:AI88) -> 743 | AJ86: =SUM(AJ87:AJ88) -> 1046 | AK86: =SUM(AK87:AK88) -> 1096 | AL86: =SUM(AL87:AL88) -> 1178 | AN86: =SUM(AN87:AN88) -> 97 | AO86: =SUM(AO87:AO88) -> 276 | AP86: =SUM(AP87:AP88) -> 412 | AQ86: =SUM(AQ87:AQ88) -> 387 | AR86: =SUM(AR87:AR88) -> 390 | AT86: =SUM(AT87:AT88) -> 2346 | AU86: =SUM(AU87:AU88) -> 3338 | AV86: =SUM(AV87:AV88) -> 4090 | AW86: =SUM(AW87:AW88) -> 4796 | AX86: =SUM(AX87:AX88) -> 5388 | AZ86: =SUM(AZ87:AZ88) -> 474 | BA86: =SUM(BA87:BA88) -> 726 | BB86: =SUM(BB87:BB88) -> 1070 | BC86: =SUM(BC87:BC88) -> 1255 | BD86: =SUM(BD87:BD88) -> 1904
B87: Equity | D87: 73 | E87: 73 | F87: 73 | G87: 73 | H87: 73 | J87: 155 | K87: 155 | L87: 155 | M87: 147 | N87: 147 | P87: 132 | Q87: 132 | R87: 132 | S87: 133 | T87: 136 | V87: 67 | W87: 79 | X87: 79 | Y87: 79 | Z87: 79 | AB87: 60 | AC87: 297 | AD87: 297 | AE87: 297 | AF87: 297 | AH87: 107 | AI87: 107 | AJ87: 107 | AK87: 107 | AL87: 107 | AN87: 31 | AO87: 48 | AP87: 48 | AQ87: 48 | AR87: 48 | AT87: 27 | AU87: 27 | AV87: 27 | AW87: 27 | AX87: 27 | AZ87: 42 | BA87: 42 | BB87: 42 | BC87: 42 | BD87: 43
...

Sheet Damodaran Data
B3: Country Data | G3: Company Data
B4: Country | C4: Africa | D4: Moody's rating | E4: Rating-based Default Spread | G4: For large non-financial service firms | L4: For smaller and riskier firms
B5: India | C5: Asia | D5: Baa3 | E5: 0.021609858 | G5: If interest coverage ratio is | L5: If interest coverage ratio is
B6: United Kingdom | C6: Western Europe | D6: Aa3 | E6: 0.0058935977 | G6: > | H6: ≤ to | I6: Rating is | J6: Spread is | L6: greater than | M6: ≤ to | N6: Rating is | O6: Spread is
B7: United States | C7: North America | D7: Aa1 | E7: 0.0027 | G7: -100000 | H7: 0.199999 | I7: D2/D | J7: 0.19 | L7: -100000 | M7: 0.499999 | N7: D2/D | O7: 0.19
B8: Abu Dhabi | C8: Middle East | D8: Aa2 | E8: 0.004853551 | G8: 0.2 | H8: 0.649999 | I8: C2/C | J8: 0.16 | L8: 0.5 | M8: 0.799999 | N8: C2/C | O8: 0.16
B9: Albania | C9: Eastern Europe & Russia | D9: Ba3 | E9: 0.035361586 | G9: 0.65 | H9: 0.799999 | I9: Ca2/CC | J9: 0.1261 | L9: 0.8 | M9: 1.249999 | N9: Ca2/CC | O9: 0.1261
B10: Andorra (Principality of) | C10: Western Europe | D10: Baa1 | E10: 0.015716261 | G10: 0.8 | H10: 1.249999 | I10: Caa/CCC | J10: 0.0885 | L10: 1.25 | M10: 1.499999 | N10: Caa/CCC | O10: 0.0885
B11: Angola | C11: Africa | D11: B3 | E11: 0.063905089 | G11: 1.25 | H11: 1.499999 | I11: B3/B- | J11: 0.0509 | L11: 1.5 | M11: 1.999999 | N11: B3/B- | O11: 0.0509
B12: Argentina | C12: Central and South America | D12: Caa3 | E12: 0.098342189 | G12: 1.5 | H12: 1.749999 | I12: B2/B | J12: 0.0321 | L12: 2 | M12: 2.499999 | N12: B2/B | O12: 0.0321
B13: Armenia | C13: Eastern Europe & Russia | D13: Ba3 | E13: 0.035361586 | G13: 1.75 | H13: 1.999999 | I13: B1/B+ | J13: 0.0275 | L13: 2.5 | M13: 2.999999 | N13: B1/B+ | O13: 0.0275
B14: Aruba | C14: Caribbean | D14: Baa3 | E14: 0.021609858 | G14: 2 | H14: 2.2499999 | I14: Ba2/BB | J14: 0.0184 | L14: 3 | M14: 3.499999 | N14: Ba2/BB | O14: 0.0184
B15: Australia | C15: Australia & New Zealand | D15: Aaa | E15: 0 | G15: 2.25 | H15: 2.49999 | I15: Ba1/BB+ | J15: 0.0138 | L15: 3.5 | M15: 3.9999999 | N15: Ba1/BB+ | O15: 0.0138
B16: Austria | C16: Western Europe | D16: Aa1 | E16: 0.0027 | G16: 2.5 | H16: 2.999999 | I16: Baa2/BBB | J16: 0.0111 | L16: 4 | M16: 4.499999 | N16: Baa2/BBB | O16: 0.0111
B17: Azerbaijan | C17: Eastern Europe & Russia | D17: Baa3 | E17: 0.021609858 | G17: 3 | H17: 4.249999 | I17: A3/A- | J17: 0.0089 | L17: 4.5 | M17: 5.999999 | N17: A3/A- | O17: 0.0089
B18: Bahamas | C18: Caribbean | D18: B1 | E18: 0.044259763 | G18: 4.25 | H18: 5.499999 | I18: A2/A | J18: 0.0078 | L18: 6 | M18: 7.499999 | N18: A2/A | O18: 0.0078
... B21: Barbados | C21: Caribbean | D21: B2 | E21: 0.054082426 | G21: 8.5 | H21: 100000 | I21: Aaa/AAA | J21: 0.004 | L21: 12.5 | M21: 100000 | N21: Aaa/AAA | O21: 0.004
B22: Belarus | C22: Eastern Europe & Russia | D22: C | E22: 0.175
B23: Belgium | C23: Western Europe | D23: Aa3 | E23: 0.0058935977
B24: Belize | C24: Central and South America | D24: Caa1 | E24: 0.073727752
B25: Benin | C25: Africa | D25: B1 | E25: 0.044259763
B26: Bermuda | C26: Caribbean | D26: A2 | E26: 0.0083203732
B27: Bolivia | C27: Central and South America | D27: Ca | E27: 0.11798751
B28: Bosnia and Herzegovina | C28: Eastern Europe & Russia | D28: B3 | E28: 0.063905089
B29: Botswana | C29: Africa | D29: A3 | E29: 0.011787195
B30: Brazil | C30: Central and South America | D30: Ba1 | E30: 0.024614437
B31: Bulgaria | C31: Eastern Europe & Russia | D31: Baa1 | E31: 0.015716261
B32: Burkina Faso | C32: Africa | D32: Caa1 | E32: 0.073727752
B33: Cambodia | C33: Asia | D33: B2 | E33: 0.054082426
... B161: Zambia | C161: Africa | D161: Caa2 | E161: 0.088519526

Sheet Control Sheet
B2: ='Input Sheet'!C5 -> Epigral Ltd. | C2: 46041 | M2: Management case
B3: Control Sheet | H3: Current Case | I3: 1 | M3: Base Case
M4: Down Case
D7: Actual | I7: Explicit Forecast Period | Q7: Terminal Value
B8: In INR Crores Other wise Stated | D8: =' Income Statement'!D6 -> 2021 | E8: =' Income Statement'!E6 -> 2022 | F8: =' Income Statement'!F6 -> 2023 | G8: =' Income Statement'!G6 -> 2024 | H8: =' Income Statement'!H6 -> 2025 | I8: =H8+1 -> 2026 | J8: =I8+1 -> 2027 | K8: =J8+1 -> 2028 | L8: =K8+1 -> 2029 | M8: =L8+1 -> 2030 | N8: =M8+1 -> 2031 | O8: =N8+1 -> 2032 | P8: =O8+1 -> 2033 | ... V8: =U8+1 -> 2039
B10: Assumption
A12: # | B12: Revenue
B14: Revenue - yoy % Growth
B15: Management Case | D15: =' Income Statement'!D12 -> 0 | E15: =' Income Statement'!E12 -> 0.77927928 | F15: =' Income Statement'!F12 -> 0.35822785 | G15: =' Income Statement'!G12 -> -0.19105312 | H15: =' Income Statement'!H12 -> 0.37903226 | I15: 0.16 | J15: 0.22 | K15: 0.25 | L15: 0.25 | M15: =L$15-(($L$15-$P$15)/($P$8-$L$8)) -> 0.2325 | N15: =M$15-(($L$15-$P$15)/($P$8-$L$8)) -> 0.215 | O15: =N$15-(($L$15-$P$15)/($P$8-$L$8)) -> 0.1975 | P15: 0.18 | Q15: 0.15 | R15: 0.14 | S15: 0.12 | T15: 0.1 | U15: 0.08 | V15: 0.05
B16: Best Case | D16: =D15 -> 0 | E16: =E15 -> 0.77927928 | F16: =F15 -> 0.35822785 | G16: =G15 -> -0.19105312 | H16: =H15 -> 0.37903226 | I16: 0.15 | J16: 0.2 | K16: 0.18 | L16: =K$16-(($K$16-$P$16)/($P$8-$K$8)) -> 0.174 | M16: =L$16-(($K$16-$P$16)/($P$8-$K$8)) -> 0.168 | N16: =M$16-(($K$16-$P$16)/($P$8-$K$8)) -> 0.162 | O16: =N$16-(($K$16-$P$16)/($P$8-$K$8)) -> 0.156 | P16: 0.15 | Q16: 0.15 | R16: 0.15 | S16: 0.15 | T16: 0.15 | U16: 0.15 | V16: 0.15
B17: Down Case | D17: =D16 -> 0 | E17: =E16 -> 0.77927928 | F17: =F16 -> 0.35822785 | G17: =G16 -> -0.19105312 | H17: =H16 -> 0.37903226 | I17: 0.13 | J17: 0.2 | K17: =J$17-(($I$17-$P$17)/($P$8-$I$8)) -> 0.19857143 | L17: =K$17-(($I$17-$P$17)/($P$8-$I$8)) -> 0.19714286 | M17: =L$17-(($I$17-$P$17)/($P$8-$I$8)) -> 0.19571429 | N17: =M$17-(($I$17-$P$17)/($P$8-$I$8)) -> 0.19428571 | O17: =N$17-(($I$17-$P$17)/($P$8-$I$8)) -> 0.19285714 | P17: 0.12 | Q17: 0.12 | R17: 0.12 | S17: 0.12 | T17: 0.12 | U17: 0.12 | V17: 0.12
B18: ="Current Case - "&CHOOSE($I$3,B15,B16,B17) -> Current Case - Management Case | I18: =CHOOSE($I$3,I15,I16,I17,) -> 0.16 | J18: =CHOOSE($I$3,J15,J16,J17,) -> 0.22 | K18: =CHOOSE($I$3,K15,K16,K17,) -> 0.25 | L18: =CHOOSE($I$3,L15,L16,L17,) -> 0.25 | M18: =CHOOSE($I$3,M15,M16,M17,) -> 0.2325 | N18: =CHOOSE($I$3,N15,N16,N17,) -> 0.215 | O18: =CHOOSE($I$3,O15,O16,O17,) -> 0.1975 | P18: =CHOOSE($I$3,P15,P16,P17,) -> 0.18 | ... V18: =CHOOSE($I$3,V15,V16,V17,) -> 0.05
A20: # | B20: COGS
B22: Gross Margins%
B23: Management Case | D23: =' Income Statement'!D14 -> 0.53558504 | E23: =' Income Statement'!E14 -> 0.50934881 | F23: =' Income Statement'!F14 -> 0.49040219 | G23: =' Income Statement'!G14 -> 0.44997408 | H23: =' Income Statement'!H14 -> 0.46941176 | I23: 0.45 | J23: 0.456 | K23: 0.456 | L23: =K$23-(($K$23-$P$23)/($P$8-$K$8)) -> 0.4608 | M23: =L$23-(($K$23-$P$23)/($P$8-$K$8)) -> 0.4656 | N23: =M$23-(($K$23-$P$23)/($P$8-$K$8)) -> 0.4704 | O23: =N$23-(($K$23-$P$23)/($P$8-$K$8)) -> 0.4752 | P23: 0.48 | Q23: 0.51 | R23: 0.51 | S23: 0.51 | T23: 0.52 | U23: 0.52 | V23: 0.52
B24: Best Case | D24: =D23 -> 0.53558504 | E24: =E23 -> 0.50934881 | F24: =F23 -> 0.49040219 | G24: =G23 -> 0.44997408 | H24: =H23 -> 0.46941176 | I24: 0.47 | J24: 0.47 | K24: 0.49 | L24: =K$24-(($K$24-$P$24)/($P$8-$K$8)) -> 0.482 | M24: =L$24-(($K$24-$P$24)/($P$8-$K$8)) -> 0.474 | N24: =M$24-(($K$24-$P$24)/($P$8-$K$8)) -> 0.466 | O24: =N$24-(($K$24-$P$24)/($P$8-$K$8)) -> 0.458 | P24: 0.45 | Q24: 0.45 | R24: 0.45 | S24: 0.45 | T24: 0.45 | U24: 0.45 | V24: 0.45
B25: Down Case | D25: =D24 -> 0.53558504 | E25: =E24 -> 0.50934881 | F25: =F24 -> 0.49040219 | G25: =G24 -> 0.44997408 | H25: =H24 -> 0.46941176 | I25: 0.45 | J25: =I$25-(($I$25-$P$25)/($P$8-$I$8)) -> 0.43 | K25: =J$25-(($I$25-$P$25)/($P$8-$I$8)) -> 0.41 | L25: =K$25-(($I$25-$P$25)/($P$8-$I$8)) -> 0.39 | M25: =L$25-(($I$25-$P$25)/($P$8-$I$8)) -> 0.37 | N25: =M$25-(($I$25-$P$25)/($P$8-$I$8)) -> 0.35 | O25: =N$25-(($I$25-$P$25)/($P$8-$I$8)) -> 0.33 | P25: 0.31 | Q25: 0.31 | R25: 0.31 | S25: 0.31 | T25: 0.31 | U25: 0.31 | V25: 0.31
B26: ="Current Case - "&CHOOSE($I$3,B23,B24,B25) -> Current Case - Management Case | I26: =CHOOSE($I$3,I23,I24,I25,) -> 0.45 | J26: =CHOOSE($I$3,J23,J24,J25,) -> 0.456 | K26: =CHOOSE($I$3,K23,K24,K25,) -> 0.456 | L26: =CHOOSE($I$3,L23,L24,L25,) -> 0.4608 | M26: =CHOOSE($I$3,M23,M24,M25,) -> 0.4656 | N26: =CHOOSE($I$3,N23,N24,N25,) -> 0.4704 | O26: =CHOOSE($I$3,O23,O24,O25,) -> 0.4752 | P26: =CHOOSE($I$3,P23,P24,P25,) -> 0.48 | ... V26: =CHOOSE($I$3,V23,V24,V25,) -> 0.52
B28: Current Case COGS | I28: =1-I26 -> 0.55 | J28: =1-J26 -> 0.544 | K28: =1-K26 -> 0.544 | L28: =1-L26 -> 0.5392 | M28: =1-M26 -> 0.5344 | N28: =1-N26 -> 0.5296 | O28: =1-O26 -> 0.5248 | P28: =1-P26 -> 0.52 | ... V28: =1-V26 -> 0.48
A30: # | B30: Selling, General & Administration (SG&A)
B32: Salaries, Wages & Bonus % Revenue
B33: Management Case | D33: ='Assumptions Working'!D409 -> 0.049457177 | E33: ='Assumptions Working'!E409 -> 0.033526757 | F33: ='Assumptions Working'!F409 -> 0.031535649 | G33: ='Assumptions Working'!G409 -> 0.041990669 | H33: ='Assumptions Working'!H409 -> 0.038431373 | I33: 0.038 | J33: 0.038 | K33: 0.038 | L33: 0.038 | M33: 0.038 | N33: 0.038 | O33: 0.038 | P33: 0.038 | Q33: 0.038 | R33: 0.038 | S33: 0.038 | T33: 0.038 | U33: 0.038 | V33: 0.038
B34: Best Case | D34: =D33 -> 0.049457177 | E34: =E33 -> 0.033526757 | F34: =F33 -> 0.031535649 | G34: =G33 -> 0.041990669 | H34: =H33 -> 0.038431373 | I34: 0.038 | J34: 0.038 | K34: 0.038 | L34: 0.038 | M34: 0.038 | N34: 0.038 | O34: 0.038 | P34: 0.038 | Q34: 0.038 | R34: 0.038 | S34: 0.038 | T34: 0.038 | U34: 0.038 | V34: 0.038
B35: Down Case | D35: =D34 -> 0.049457177 | E35: =E34 -> 0.033526757 | F35: =F34 -> 0.031535649 | G35: =G34 -> 0.041990669 | H35: =H34 -> 0.038431373 | I35: 0.038 | J35: 0.038 | K35: 0.038 | L35: 0.038 | M35: 0.038 | N35: 0.038 | O35: 0.038 | P35: 0.038 | Q35: 0.038 | R35: 0.038 | S35: 0.038 | T35: 0.038 | U35: 0.038 | V35: 0.038
B36: ="Current Case - "&CHOOSE($I$3,B33,B34,B35) -> Current Case - Management Case | I36: =CHOOSE($I$3,I33,I34,I35,) -> 0.038 | J36: =CHOOSE($I$3,J33,J34,J35,) -> 0.038 | K36: =CHOOSE($I$3,K33,K34,K35,) -> 0.038 | L36: =CHOOSE($I$3,L33,L34,L35,) -> 0.038 | M36: =CHOOSE($I$3,M33,M34,M35,) -> 0.038 | N36: =CHOOSE($I$3,N33,N34,N35,) -> 0.038 | O36: =CHOOSE($I$3,O33,O34,O35,) -> 0.038 | P36: =CHOOSE($I$3,P33,P34,P35,) -> 0.038 | ... V36: =CHOOSE($I$3,V33,V34,V35,) -> 0.038
B38: Power & Fuel Cost % Revenue
B39: Management Case | D39: ='Assumptions Working'!D412 -> 0.031363088 | E39: ='Assumptions Working'!E412 -> 0.064474533 | F39: ='Assumptions Working'!F412 -> 0.070383912 | G39: ='Assumptions Working'!G412 -> 0.073094868 | H39: ='Assumptions Working'!H412 -> 0.070588235 | I39: 0.07 | J39: 0.07 | K39: 0.07 | L39: 0.07 | M39: 0.07 | N39: 0.07 | O39: 0.07 | P39: 0.07 | Q39: 0.07 | R39: 0.07 | S39: 0.07 | T39: 0.07 | U39: 0.07 | V39: 0.07
B40: Best Case | D40: =D39 -> 0.031363088 | E40: =E39 -> 0.064474533 | F40: =F39 -> 0.070383912 | G40: =G39 -> 0.073094868 | H40: =H39 -> 0.070588235 | I40: 0.07 | J40: 0.07 | K40: 0.07 | L40: 0.07 | M40: 0.07 | N40: 0.07 | O40: 0.07 | P40: 0.07 | Q40: 0.07 | R40: 0.07 | S40: 0.07 | T40: 0.07 | U40: 0.07 | V40: 0.07
B41: Down Case | D41: =D40 -> 0.031363088 | E41: =E40 -> 0.064474533 | F41: =F40 -> 0.070383912 | G41: =G40 -> 0.073094868 | H41: =H40 -> 0.070588235 | I41: 0.07 | J41: 0.07 | K41: 0.07 | L41: 0.07 | M41: 0.07 | N41: 0.07 | O41: 0.07 | P41: 0.07 | Q41: 0.07 | R41: 0.07 | S41: 0.07 | T41: 0.07 | U41: 0.07 | V41: 0.07
B42: ="Current Case - "&CHOOSE($I$3,B39,B40,B41) -> Current Case - Management Case | I42: =CHOOSE($I$3,I39,I40,I41,) -> 0.07 | J42: =CHOOSE($I$3,J39,J40,J41,) -> 0.07 | K42: =CHOOSE($I$3,K39,K40,K41,) -> 0.07 | L42: =CHOOSE($I$3,L39,L40,L41,) -> 0.07 | M42: =CHOOSE($I$3,M39,M40,M41,) -> 0.07 | N42: =CHOOSE($I$3,N39,N40,N41,) -> 0.07 | O42: =CHOOSE($I$3,O39,O40,O41,) -> 0.07 | P42: =CHOOSE($I$3,P39,P40,P41,) -> 0.07 | ... V42: =CHOOSE($I$3,V39,V40,V41,) -> 0.07
B44: Other Operating Expenses % Revenue
B45: Management Case | D45: ='Assumptions Working'!D415 -> 0.053075995 | E45: ='Assumptions Working'!E415 -> 0.040618956 | F45: ='Assumptions Working'!F415 -> 0.036563071 | G45: ='Assumptions Working'!G415 -> 0.044582685 | H45: ='Assumptions Working'!H415 -> 0.036862745 | I45: 0.041 | J45: 0.041 | K45: 0.041 | L45: 0.041 | M45: 0.041 | N45: 0.041 | O45: 0.041 | P45: 0.041 | Q45: 0.041 | R45: 0.041 | S45: 0.041 | T45: 0.041 | U45: 0.041 | V45: 0.041
B46: Best Case | D46: =D45 -> 0.053075995 | E46: =E45 -> 0.040618956 | F46: =F45 -> 0.036563071 | G46: =G45 -> 0.044582685 | H46: =H45 -> 0.036862745 | I46: 0.041 | J46: 0.041 | K46: 0.041 | L46: 0.041 | M46: 0.041 | N46: 0.041 | O46: 0.041 | P46: 0.041 | Q46: 0.041 | R46: 0.041 | S46: 0.041 | T46: 0.041 | U46: 0.041 | V46: 0.041
B47: Down Case | D47: =D46 -> 0.053075995 | E47: =E46 -> 0.040618956 | F47: =F46 -> 0.036563071 | G47: =G46 -> 0.044582685 | H47: =H46 -> 0.036862745 | I47: 0.041 | J47: 0.041 | K47: 0.041 | L47: 0.041 | M47: 0.041 | N47: 0.041 | O47: 0.041 | P47: 0.041 | Q47: 0.041 | R47: 0.041 | S47: 0.041 | T47: 0.041 | U47: 0.041 | V47: 0.041
B48: ="Current Case - "&CHOOSE($I$3,B45,B46,B47) -> Current Case - Management Case | I48: =CHOOSE($I$3,I45,I46,I47,) -> 0.041 | J48: =CHOOSE($I$3,J45,J46,J47,) -> 0.041 | K48: =CHOOSE($I$3,K45,K46,K47,) -> 0.041 | L48: =CHOOSE($I$3,L45,L46,L47,) -> 0.041 | M48: =CHOOSE($I$3,M45,M46,M47,) -> 0.041 | N48: =CHOOSE($I$3,N45,N46,N47,) -> 0.041 | O48: =CHOOSE($I$3,O45,O46,O47,) -> 0.041 | P48: =CHOOSE($I$3,P45,P46,P47,) -> 0.041 | ... V48: =CHOOSE($I$3,V45,V46,V47,) -> 0.041
B50: Other SG&A Expenses % Revenue
B51: Management Case | D51: ='Assumptions Working'!D418 -> 0.08588661 | E51: ='Assumptions Working'!E418 -> 0.041779497 | F51: ='Assumptions Working'!F418 -> 0.036837294 | G51: ='Assumptions Working'!G418 -> 0.041109383 | H51: ='Assumptions Working'!H418 -> 0.04454902 | I51: 0.042 | J51: 0.042 | K51: 0.042 | L51: 0.042 | M51: 0.042 | N51: 0.042 | O51: 0.042 | P51: 0.042 | Q51: 0.042 | R51: 0.042 | S51: 0.042 | T51: 0.042 | U51: 0.042 | V51: 0.042
B52: Best Case | D52: =D51 -> 0.08588661 | E52: =E51 -> 0.041779497 | F52: =F51 -> 0.036837294 | G52: =G51 -> 0.041109383 | H52: =H51 -> 0.04454902 | I52: 0.042 | J52: 0.042 | K52: 0.042 | L52: 0.042 | M52: 0.042 | N52: 0.042 | O52: 0.042 | P52: 0.042 | Q52: 0.042 | R52: 0.042 | S52: 0.042 | T52: 0.042 | U52: 0.042 | V52: 0.042
B53: Down Case | D53: =D52 -> 0.08588661 | E53: =E52 -> 0.041779497 | F53: =F52 -> 0.036837294 | G53: =G52 -> 0.041109383 | H53: =H52 -> 0.04454902 | I53: 0.042 | J53: 0.042 | K53: 0.042 | L53: 0.042 | M53: 0.042 | N53: 0.042 | O53: 0.042 | P53: 0.042 | Q53: 0.042 | R53: 0.042 | S53: 0.042 | T53: 0.042 | U53: 0.042 | V53: 0.042
B54: ="Current Case - "&CHOOSE($I$3,B51,B52,B53) -> Current Case - Management Case | I54: =CHOOSE($I$3,I51,I52,I53,) -> 0.042 | J54: =CHOOSE($I$3,J51,J52,J53,) -> 0.042 | K54: =CHOOSE($I$3,K51,K52,K53,) -> 0.042 | L54: =CHOOSE($I$3,L51,L52,L53,) -> 0.042 | M54: =CHOOSE($I$3,M51,M52,M53,) -> 0.042 | N54: =CHOOSE($I$3,N51,N52,N53,) -> 0.042 | O54: =CHOOSE($I$3,O51,O52,O53,) -> 0.042 | P54: =CHOOSE($I$3,P51,P52,P53,) -> 0.042 | ... V54: =CHOOSE($I$3,V51,V52,V53,) -> 0.042
...

Sheet Assumptions Working
A2: # | B2: Revenue Growth
B4: Company Historical Growth
J5: CAGR
B6: =' Income Statement'!B6 -> Particulars | D6: =' Income Statement'!D6 -> 2021 | E6: =' Income Statement'!E6 -> 2022 | F6: =' Income Statement'!F6 -> 2023 | G6: =' Income Statement'!G6 -> 2024 | H6: =' Income Statement'!H6 -> 2025 | J6: 3 Years | K6: 5 Years
B7: Revenue from Operations (Net) | D7: =' Income Statement'!D8 -> 829 | E7: =' Income Statement'!E8 -> 1551 | F7: =' Income Statement'!F8 -> 2188 | G7: =' Income Statement'!G8 -> 1929 | H7: =' Income Statement'!H8 -> 2550 | J7: =_xlfn.RRI(3,F7,H7) -> 0.052359892 | K7: =_xlfn.RRI(5,D7,H7) -> 0.25197925
B8: Sales Growth | E8: =E7/D7-1 -> 0.87092883 | F8: =F7/E7-1 -> 0.41070277 | G8: =G7/F7-1 -> -0.11837294 | H8: =H7/G7-1 -> 0.32192846
B11: Global Speciality Chemical
B13: GVR | D13: https://www.grandviewresearch.com/industry-analysis/specialty-chemicals-market
B14: The global specialty chemicals market was valued at approximately USD 978.97 billion in 2024 and is projected to reach USD 1,312.78 billion over the forecast period.
B15: growing at a CAGR of 5% from 2025 to 2030
B17: Fortune Business Insight | D17: https://www.fortunebusinessinsights.com/specialty-chemicals-market-105517
B18: The global specialty chemicals market size was USD 757.98 billion in 2025 and is projected to grow from USD 796.84 billion in 2026 to USD 1,167.22 billion in 2034 at a CAGR of 4.90% during the forecast period 2026-2034. Asia Pacific dominated the specialty chemicals market with a market share of 49.60% in 2025. Moreover, the specialty chemical market size in the U.S. is projected to grow significantly, reaching an estimated value of USD 152.36 billion by 2032, driven by expanding demand for construction chemicals on account of an increase in investments in infrastructure projects.
B21: Precedence research | D21: https://www.precedenceresearch.com/specialty-chemicals-market
B43: Indian Chlor alkali market Growth
B45: IMARC | D45: http://imarcgroup.com/india-chlor-alkali-market
B47: CAGR Growth 2025-2033 | D47: 0.0418
B66: Mobility Foresight | D66: https://mobilityforesights.com/product/india-chlor-alkali-market#:~:text=India%20Chlor%2DAlkali%20Market%20Size%20and%20Forecast,expansion%20across%20the%20forecast%20horizon.
B68: 25 Revenue | D68: USD 84.6 billion in 2025
B69: CAGR Growth 2025-2032 | D69: 0.0419
B72: Global Research Consulting | D72: https://www.omrglobal.com/industry-reports/india-chlor-alkali-market-size#:~:text=Indian%20chlor%20alkali%20market%20is,friendly%20ones%20like%20membrane%20cells.
B74: 0.065
D76: https://www.fortunebusinessinsights.com/industry-reports/chlor-alkali-market-101720#:~:text=The%20global%20chlor%20alkali%20market,the%20share%20in%20production%20technologies.
B77: The global chlor alkali market size was USD 52.23 billion in 2023 and is projected to grow from USD 53.22 billion in 2024 to USD 62.24 billion by 2032 at a CAGR of 1.94% during the forecast period.
B81: Mordor Intelligence
B83: CAGR over 2026-2031 | D83: 0.0299
B84: Asia-Pacific retained 62.15% of the chlor-alkali market size in 2025 and is projected to compound at a 3.12% CAGR through 2031
B85: Source: https://www.mordorintelligence.com/industry-reports/chlor-alkali-market
V86: Category | W86: Specific Product(s) | X86: Status / Capacity (approx.) | Y86: Key End-Use Industries
V87: Primary Chlor-Alkali | W87: Caustic Soda (Lye & Flakes) | X87: 400,000 TPA (4th largest in India) | Y87: Alumina, Textiles, Soaps
W88: Caustic Potash (Lye & Flakes) | X88: 21,000 TPA (3rd largest in India) | Y88: Soaps, Fertilizers, Pharma
W89: Chlorine & Hydrogen | X89: Captive Feedstock | Y89: Baseline for all derivatives
V90: Industrial By-products | W90: Hydrochloric Acid (HCl) | X90: Related product | Y90: Steel pickling, Water treatment
W91: Sodium Hypochlorite | X91: Related product | Y91: Disinfectant, Bleaching
W92: Diluted Sulphuric Acid | X92: Process byproduct | Y92: Industrial chemical processes
V93: Chloromethanes (CMS) | W93: Methyl Chloride, MDC, Chloroform, CTC | X93: 50,000 TPA (5th largest in India) | Y93: Pharma solvents, Refrigerants
V94: CPVC Value Chain | W94: CPVC Resin | X94: 75,000 TPA (Expanding to 150,000) | Y94: Heat-resistant plumbing (PVC)
W95: CPVC Compound | X95: 35,000 TPA (Commissioned 2024) | Y95: Ready-to-use pipe material
V96: Specialty Derivatives | W96: Epichlorohydrin (ECH) | X96: 50,000 TPA (Expanding to 100,000) | Y96: Epoxy Resins (Windmills, Auto)
W97: Hydrogen Peroxide (H2​O2​) | X97: 60,000 TPA (3rd largest in India) | Y97: Paper, Pulp, Textile bleaching
V98: Chlorotoluenes | W98: OCT, PCT, DCT (8-9 total products) | X98: Commissioned Q4 FY25 | Y98: Agrochemicals, Pharma (APIs)
...

Sheet Schedules
B2: ='Input Sheet'!C5 -> Epigral Ltd.
B3: Schedules | E3: Current Case | F3: 2
D7: Actual | I7: Explicit Forecast Period | Q7: Terminal Value
B8: In INR Crores Other wise Stated | D8: =' Income Statement'!D6 -> 2021 | E8: =' Income Statement'!E6 -> 2022 | F8: =' Income Statement'!F6 -> 2023 | G8: =' Income Statement'!G6 -> 2024 | H8: =' Income Statement'!H6 -> 2025 | I8: =H8+1 -> 2026 | J8: =I8+1 -> 2027 | K8: =J8+1 -> 2028 | L8: =K8+1 -> 2029 | M8: =L8+1 -> 2030 | N8: =M8+1 -> 2031 | O8: =N8+1 -> 2032 | P8: =O8+1 -> 2033 | ... V8: =U8+1 -> 2039
A10: # | B10: Revenue Schedule
B12: Revenue | D12: =' Income Statement'!D8 -> 829 | E12: =' Income Statement'!E8 -> 1551 | F12: =' Income Statement'!F8 -> 2188 | G12: =' Income Statement'!G8 -> 1929 | H12: =' Income Statement'!H8 -> 2550 | I12: =H12*(1+I14) -> 2958 | J12: =I12*(1+J14) -> 3608.76 | K12: =J12*(1+K14) -> 4510.95 | L12: =K12*(1+L14) -> 5638.6875 | M12: =L12*(1+M14) -> 6949.6823 | N12: =M12*(1+N14) -> 8443.864 | O12: =N12*(1+O14) -> 10111.527 | P12: =O12*(1+P14) -> 11931.602 | ... V12: =U12*(1+V14) -> 21853.712
B14: Growth YoY | E14: =E12/D12-1 -> 0.87092883 | F14: =F12/E12-1 -> 0.41070277 | G14: =G12/F12-1 -> -0.11837294 | H14: =H12/G12-1 -> 0.32192846 | I14: ='Control Sheet'!I18 -> 0.16 | J14: ='Control Sheet'!J18 -> 0.22 | K14: ='Control Sheet'!K18 -> 0.25 | L14: ='Control Sheet'!L18 -> 0.25 | M14: ='Control Sheet'!M18 -> 0.2325 | N14: ='Control Sheet'!N18 -> 0.215 | O14: ='Control Sheet'!O18 -> 0.1975 | P14: ='Control Sheet'!P18 -> 0.18 | ... V14: ='Control Sheet'!V18 -> 0.05
A16: # | B16: COGS Schedule
B18: Cogs | D18: =' Income Statement'!D9*-1 -> 385 | E18: =' Income Statement'!E9*-1 -> 761 | F18: =' Income Statement'!F9*-1 -> 1115 | G18: =' Income Statement'!G9*-1 -> 1061 | H18: =' Income Statement'!H9*-1 -> 1353 | I18: =I12*I20 -> 1626.9 | J18: =J12*J20 -> 1963.1654 | K18: =K12*K20 -> 2453.9568 | L18: =L12*L20 -> 3040.3803 | M18: =M12*M20 -> 3713.9102 | N18: =N12*N20 -> 4471.8704 | O18: =O12*O20 -> 5306.5295 | P18: =P12*P20 -> 6204.4331 | ... V18: =V12*V20 -> 10489.782
B20: Cogs % Revenue | I20: ='Control Sheet'!I28 -> 0.55 | J20: ='Control Sheet'!J28 -> 0.544 | K20: ='Control Sheet'!K28 -> 0.544 | L20: ='Control Sheet'!L28 -> 0.5392 | M20: ='Control Sheet'!M28 -> 0.5344 | N20: ='Control Sheet'!N28 -> 0.5296 | O20: ='Control Sheet'!O28 -> 0.5248 | P20: ='Control Sheet'!P28 -> 0.52 | ... V20: ='Control Sheet'!V28 -> 0.48
A22: # | B22: SG&A (Excluding Depreciation & Interest Expenses) Schedule
B24: Salaries, Wages & Bonus
B26: Salaries, Wages & Bonus | D26: ='Assumptions Working'!D381 -> 41 | E26: ='Assumptions Working'!E381 -> 52 | F26: ='Assumptions Working'!F381 -> 69 | G26: ='Assumptions Working'!G381 -> 81 | H26: ='Assumptions Working'!H381 -> 98 | I26: =I$12*I27 -> 112.404 | J26: =J$12*J27 -> 137.13288 | K26: =K$12*K27 -> 171.4161 | L26: =L$12*L27 -> 214.27013 | M26: =M$12*M27 -> 264.08793 | N26: =N$12*N27 -> 320.86683 | O26: =O$12*O27 -> 384.23803 | P26: =P$12*P27 -> 453.40088 | ... V26: =V$12*V27 -> 830.44106
B27: Salaries, Wages & Bonus % Revenue | D27: ='Assumptions Working'!D409 -> 0.049457177 | E27: ='Assumptions Working'!E409 -> 0.033526757 | F27: ='Assumptions Working'!F409 -> 0.031535649 | G27: ='Assumptions Working'!G409 -> 0.041990669 | H27: ='Assumptions Working'!H409 -> 0.038431373 | I27: ='Control Sheet'!I36 -> 0.038 | J27: ='Control Sheet'!J36 -> 0.038 | K27: ='Control Sheet'!K36 -> 0.038 | L27: ='Control Sheet'!L36 -> 0.038 | M27: ='Control Sheet'!M36 -> 0.038 | N27: ='Control Sheet'!N36 -> 0.038 | O27: ='Control Sheet'!O36 -> 0.038 | P27: ='Control Sheet'!P36 -> 0.038 | ... V27: ='Control Sheet'!V36 -> 0.038
B29: Power & Fuel Cost
B31: Power & Fuel Cost | D31: ='Assumptions Working'!D382 -> 26 | E31: ='Assumptions Working'!E382 -> 100 | F31: ='Assumptions Working'!F382 -> 154 | G31: ='Assumptions Working'!G382 -> 141 | H31: ='Assumptions Working'!H382 -> 180 | I31: =I$12*I32 -> 207.06 | J31: =J$12*J32 -> 252.6132 | K31: =K$12*K32 -> 315.7665 | L31: =L$12*L32 -> 394.70813 | M31: =M$12*M32 -> 486.47776 | N31: =N$12*N32 -> 591.07048 | O31: =O$12*O32 -> 707.8069 | P31: =P$12*P32 -> 835.21215 | ... V31: =V$12*V32 -> 1529.7598
B32: Power & Fuel Cost % Revenue | D32: ='Assumptions Working'!D412 -> 0.031363088 | E32: ='Assumptions Working'!E412 -> 0.064474533 | F32: ='Assumptions Working'!F412 -> 0.070383912 | G32: ='Assumptions Working'!G412 -> 0.073094868 | H32: ='Assumptions Working'!H412 -> 0.070588235 | I32: ='Control Sheet'!I42 -> 0.07 | J32: ='Control Sheet'!J42 -> 0.07 | K32: ='Control Sheet'!K42 -> 0.07 | L32: ='Control Sheet'!L42 -> 0.07 | M32: ='Control Sheet'!M42 -> 0.07 | N32: ='Control Sheet'!N42 -> 0.07 | O32: ='Control Sheet'!O42 -> 0.07 | P32: ='Control Sheet'!P42 -> 0.07 | ... V32: ='Control Sheet'!V42 -> 0.07
B34: Other Operating Expenses
B36: Other Operating Expenses | D36: ='Assumptions Working'!D387 -> 44 | E36: ='Assumptions Working'!E387 -> 63 | F36: ='Assumptions Working'!F387 -> 80 | G36: ='Assumptions Working'!G387 -> 86 | H36: ='Assumptions Working'!H387 -> 94 | I36: =I$12*I37 -> 121.278 | J36: =J$12*J37 -> 147.95916 | K36: =K$12*K37 -> 184.94895 | L36: =L$12*L37 -> 231.18619 | M36: =M$12*M37 -> 284.93698 | N36: =N$12*N37 -> 346.19843 | O36: =O$12*O37 -> 414.57262 | P36: =P$12*P37 -> 489.19569 | ... V36: =V$12*V37 -> 896.00219
B37: Other Expenses % Revenue | D37: ='Assumptions Working'!D415 -> 0.053075995 | E37: ='Assumptions Working'!E415 -> 0.040618956 | F37: ='Assumptions Working'!F415 -> 0.036563071 | G37: ='Assumptions Working'!G415 -> 0.044582685 | H37: ='Assumptions Working'!H415 -> 0.036862745 | I37: ='Control Sheet'!I48 -> 0.041 | J37: ='Control Sheet'!J48 -> 0.041 | K37: ='Control Sheet'!K48 -> 0.041 | L37: ='Control Sheet'!L48 -> 0.041 | M37: ='Control Sheet'!M48 -> 0.041 | N37: ='Control Sheet'!N48 -> 0.041 | O37: ='Control Sheet'!O48 -> 0.041 | P37: ='Control Sheet'!P48 -> 0.041 | ... V37: ='Control Sheet'!V48 -> 0.041
B39: Other SG&A Expenses
B41: Other SG&A Expenses | D41: ='Assumptions Working'!D417 -> 71.2 | E41: ='Assumptions Working'!E417 -> 64.8 | F41: ='Assumptions Working'!F417 -> 80.6 | G41: ='Assumptions Working'!G417 -> 79.3 | H41: ='Assumptions Working'!H417 -> 113.6 | I41: =I$12*I37 -> 121.278 | J41: =J$12*J37 -> 147.95916 | K41: =K$12*K37 -> 184.94895 | L41: =L$12*L37 -> 231.18619 | M41: =M$12*M37 -> 284.93698 | N41: =N$12*N37 -> 346.19843 | O41: =O$12*O37 -> 414.57262 | P41: =P$12*P37 -> 489.19569 | ... V41: =V$12*V37 -> 896.00219
B42: Other SG&A Expenses % Revenue | D42: ='Assumptions Working'!D418 -> 0.08588661 | E42: ='Assumptions Working'!E418 -> 0.041779497 | F42: ='Assumptions Working'!F418 -> 0.036837294 | G42: ='Assumptions Working'!G418 -> 0.041109383 | H42: ='Assumptions Working'!H418 -> 0.04454902 | I42: ='Control Sheet'!I54 -> 0.042 | J42: ='Control Sheet'!J54 -> 0.042 | K42: ='Control Sheet'!K54 -> 0.042 | L42: ='Control Sheet'!L54 -> 0.042 | M42: ='Control Sheet'!M54 -> 0.042 | N42: ='Control Sheet'!N54 -> 0.042 | O42: ='Control Sheet'!O54 -> 0.042 | P42: ='Control Sheet'!P54 -> 0.042 | ... V42: ='Control Sheet'!V54 -> 0.042
B44: Total SG&A (Excluding Depriciation & Interest Expense) | D44: =D41+D36+D31+D26 -> 182.2 | E44: =E41+E36+E31+E26 -> 279.8 | F44: =F41+F36+F31+F26 -> 383.6 | G44: =G41+G36+G31+G26 -> 387.3 | H44: =H41+H36+H31+H26 -> 485.6 | I44: =I41+I36+I31+I26 -> 562.02 | J44: =J41+J36+J31+J26 -> 685.6644 | K44: =K41+K36+K31+K26 -> 857.0805 | ... V44: =V41+V36+V31+V26 -> 4152.2053
B45: Total SG&A % Sales | D45: =D44/D12 -> 0.21978287 | E45: =E44/E12 -> 0.18039974 | F45: =F44/F12 -> 0.17531993 | G45: =G44/G12 -> 0.2007776 | H45: =H44/H12 -> 0.19043137 | I45: =I44/I12 -> 0.19 | J45: =J44/J12 -> 0.19 | K45: =K44/K12 -> 0.19 | ... V45: =V44/V12 -> 0.19
A47: # | B47: Non Current Asset Schedule
B49: Property, Plant and Equipment
B50: Opening PP& E | D50: =D70 -> 0 | E50: =E70 -> 0 | F50: =F70 -> 0 | G50: =G70 -> 0 | I50: 2219 | J50: =I53 -> 2507.5271 | K50: =J53 -> 2903.1971 | L50: =K53 -> 3395.2957 | M50: =L53 -> 3973.1086 | N50: =M53 -> 4625.9214 | O50: =N53 -> 5343.02 | P50: =O53 -> 6113.69 | Q50: =P53 -> 6927.2171 | ... V50: =U53 -> 10181.027
B51: Add: Capex During the Year | I51: ='Assumptions Working'!E731 -> 450 | J51: ='Assumptions Working'!F731 -> 600 | K51: ='Assumptions Working'!G731 -> 750 | L51: ='Assumptions Working'!H731 -> 900 | M51: ='Assumptions Working'!I731 -> 1050 | N51: ='Assumptions Working'!J731 -> 1200 | O51: ='Assumptions Working'!K731 -> 1350 | P51: ='Assumptions Working'!L731 -> 1500 | ... V51: ='Assumptions Working'!R731 -> 1897.9785
B52: Less: Depreciation during the year | D52: =' Income Statement'!D26*-1 -> 70.77 | E52: =' Income Statement'!E26*-1 -> 82.67 | F52: =' Income Statement'!F26*-1 -> 105.72 | G52: =' Income Statement'!G26*-1 -> 120.33 | H52: =' Income Statement'!H26*-1 -> 129.33 | I52: =H52+I51/$C$71 -> 161.47286 | J52: =I52+J51/$C$71 -> 204.33 | K52: =J52+K51/$C$71 -> 257.90143 | L52: =K52+L51/$C$71 -> 322.18714 | M52: =L52+M51/$C$71 -> 397.18714 | N52: =M52+N51/$C$71 -> 482.90143 | O52: =N52+O51/$C$71 -> 579.33 | P52: =O52+P51/$C$71 -> 686.47286 | ... V52: =U52+V51/$C$71 -> 1425.5758
B53: Closing PP&E | D53: =D73 -> 1070.65 | E53: =E73 -> 1039.4 | F53: =F73 -> 1778.85 | G53: =G73 -> 1744.68 | H53: =H73 -> 2219.39 | I53: =I50+I51+-I52 -> 2507.5271 | J53: =J50+J51+-J52 -> 2903.1971 | K53: =K50+K51+-K52 -> 3395.2957 | L53: =L50+L51+-L52 -> 3973.1086 | M53: =M50+M51+-M52 -> 4625.9214 | N53: =N50+N51+-N52 -> 5343.02 | O53: =O50+O51+-O52 -> 6113.69 | P53: =P50+P51+-P52 -> 6927.2171 | ... V53: =V50+V51+-V52 -> 10653.43
B54: YoY Growth% | J54: =J53/I53-1 -> 0.15779291 | K54: =K53/J53-1 -> 0.16950229 | L54: =L53/K53-1 -> 0.17018042 | M54: =M53/L53-1 -> 0.16430783 | N54: =N53/M53-1 -> 0.15501746 | O54: =O53/N53-1 -> 0.14423865 | P54: =P53/O53-1 -> 0.13306647 | Q54: =Q53/P53-1 -> 0.11001511 | ... V54: =V53/U53-1 -> 0.046400297
B56: Other Non-current Assets
B57: Other Non-current Assets | D57: =' Balance Sheet'!D20 -> 39.2 | E57: =' Balance Sheet'!E20 -> 19.8 | F57: =' Balance Sheet'!F20 -> 51 | G57: =' Balance Sheet'!G20 -> 43.2 | H57: =' Balance Sheet'!H20 -> 76 | I57: =H57*(1+I58) -> 76 | J57: =I57*(1+J58) -> 76 | K57: =J57*(1+K58) -> 76 | L57: =K57*(1+L58) -> 76 | M57: =L57*(1+M58) -> 76 | N57: =M57*(1+N58) -> 76 | O57: =N57*(1+O58) -> 76 | P57: =O57*(1+P58) -> 76 | ... V57: =U57*(1+V58) -> 76
B58: % Revenue | D58: =D57/D12 -> 0.047285887 | E58: =E57/E12 -> 0.012765957 | F58: =F57/F12 -> 0.023308958 | G58: =G57/G12 -> 0.022395023 | H58: =H57/H12 -> 0.029803922 | I58: ='Control Sheet'!I65 -> 0 | J58: ='Control Sheet'!J65 -> 0 | K58: ='Control Sheet'!K65 -> 0 | L58: ='Control Sheet'!L65 -> 0 | M58: ='Control Sheet'!M65 -> 0 | N58: ='Control Sheet'!N65 -> 0 | O58: ='Control Sheet'!O65 -> 0 | P58: ='Control Sheet'!P65 -> 0 | ... V58: ='Control Sheet'!V65 -> 0
B60: CWIP
B61: CWIP | D61: =' Balance Sheet'!D19 -> 126 | E61: =' Balance Sheet'!E19 -> 589 | F61: =' Balance Sheet'!F19 -> 158 | G61: =' Balance Sheet'!G19 -> 483 | H61: =' Balance Sheet'!H19 -> 64 | I61: =H61 -> 64 | J61: =I61 -> 64 | K61: =J61 -> 64 | L61: =K61 -> 64 | M61: =L61 -> 64 | N61: =M61 -> 64 | O61: =N61 -> 64 | P61: =O61 -> 64 | ... V61: =U61 -> 64
I62: ='Control Sheet'!I71 -> 0 | J62: ='Control Sheet'!J71 -> 0 | K62: ='Control Sheet'!K71 -> 0 | L62: ='Control Sheet'!L71 -> 0 | M62: ='Control Sheet'!M71 -> 0 | N62: ='Control Sheet'!N71 -> 0 | O62: ='Control Sheet'!O71 -> 0 | P62: ='Control Sheet'!P71 -> 0 | ... V62: ='Control Sheet'!V71 -> 0
B64: Intangible Non Current Assets
B65: Intangible Non current Assets | D65: =' Balance Sheet'!D18 -> 31.35 | E65: =' Balance Sheet'!E18 -> 28.6 | F65: =' Balance Sheet'!F18 -> 25.15 | G65: =' Balance Sheet'!G18 -> 22.32 | H65: =' Balance Sheet'!H18 -> 19 | I65: =H65*(1+I66) -> 16 | J65: =I65*(1+J66) -> 13 | K65: =J65*(1+K66) -> 10 | L65: =K65*(1+L66) -> 7 | M65: 4 | N65: =M65*(1+N66) -> 0 | O65: =N65*(1+O66) -> 0 | P65: =O65*(1+P66) -> 0 | Q65: =P65*(1+Q66) -> 0 | R65: =Q65*(1+R66) -> 0 | S65: =R65*(1+S66) -> 0 | T65: =S65*(1+T66) -> 0 | U65: =T65*(1+U66) -> 0 | V65: =U65*(1+V66) -> 0
...

Sheet 3 Statement Model
S1: +
B2: ='Input Sheet'!C5 -> Epigral Ltd.
B3: Three Statement Model | H3: Current Case | I3: 2
X6: CAGR
D7: Actual | I7: Explicit Forecast Period | Q7: Terminal Value | X7: 8 Years | Y7: 5 Years | Z7: 3 Years
B8: In INR Crores Other wise Stated | D8: =Schedules!D8 -> 2021 | E8: =Schedules!E8 -> 2022 | F8: =Schedules!F8 -> 2023 | G8: =Schedules!G8 -> 2024 | H8: =Schedules!H8 -> 2025 | I8: =H8+1 -> 2026 | J8: =I8+1 -> 2027 | K8: =J8+1 -> 2028 | L8: =K8+1 -> 2029 | M8: =L8+1 -> 2030 | N8: =M8+1 -> 2031 | O8: =N8+1 -> 2032 | P8: =O8+1 -> 2033 | ... V8: =U8+1 -> 2039
A10: # | B10: Income Statement | X10: =V8-N8 -> 8 | Y10: =V8-Q8 -> 5 | Z10: =V8-S8 -> 3
B12: Revenue | D12: =Schedules!D12 -> 829 | E12: =Schedules!E12 -> 1551 | F12: =Schedules!F12 -> 2188 | G12: =Schedules!G12 -> 1929 | H12: =Schedules!H12 -> 2550 | I12: =Schedules!I12 -> 2958 | J12: =Schedules!J12 -> 3608.76 | K12: =Schedules!K12 -> 4510.95 | ... V12: =Schedules!V12 -> 21853.712 | X12: =_xlfn.RRI($V$8-$N$8,N12,V12) -> 0.12621938 | Y12: =_xlfn.RRI($V$8-$Q$8,Q12,V12) -> 0.09755356 | Z12: =_xlfn.RRI($V$8-$S$8,S12,V12) -> 0.076469956
B13: Less: Cost of Goods Sold | D13: =Schedules!D18 -> 385 | E13: =Schedules!E18 -> 761 | F13: =Schedules!F18 -> 1115 | G13: =Schedules!G18 -> 1061 | H13: =Schedules!H18 -> 1353 | I13: =Schedules!I18 -> 1626.9 | J13: =Schedules!J18 -> 1963.1654 | K13: =Schedules!K18 -> 2453.9568 | ... V13: =Schedules!V18 -> 10489.782 | X13: =_xlfn.RRI($V$8-$N$8,N13,V13) -> 0.11246064 | Y13: =_xlfn.RRI($V$8-$Q$8,Q13,V13) -> 0.093036725 | Z13: =_xlfn.RRI($V$8-$S$8,S13,V13) -> 0.069096643
B14: Gross Profit | D14: =D12-D13 -> 444 | E14: =E12-E13 -> 790 | F14: =F12-F13 -> 1073 | G14: =G12-G13 -> 868 | H14: =H12-H13 -> 1197 | I14: =I12-I13 -> 1331.1 | J14: =J12-J13 -> 1645.5946 | K14: =K12-K13 -> 2056.9932 | ... V14: =V12-V13 -> 11363.93 | X14: =_xlfn.RRI($V$8-$N$8,N14,V14) -> 0.14042046 | Y14: =_xlfn.RRI($V$8-$Q$8,Q14,V14) -> 0.10182433 | Z14: =_xlfn.RRI($V$8-$S$8,S14,V14) -> 0.083460216
B16: Gross Margins | D16: =D14/D12 -> 0.53558504 | E16: =E14/E12 -> 0.50934881 | F16: =F14/F12 -> 0.49040219 | G16: =G14/G12 -> 0.44997408 | H16: =H14/H12 -> 0.46941176 | I16: =I14/I12 -> 0.45 | J16: =J14/J12 -> 0.456 | K16: =K14/K12 -> 0.456 | ... V16: =V14/V12 -> 0.52
B18: Less: SG&A Expense (Excluding Depreciation & Interest)
B19: =Schedules!B24 -> Salaries, Wages & Bonus | D19: =Schedules!D26 -> 41 | E19: =Schedules!E26 -> 52 | F19: =Schedules!F26 -> 69 | G19: =Schedules!G26 -> 81 | H19: =Schedules!H26 -> 98 | I19: =Schedules!I26 -> 112.404 | J19: =Schedules!J26 -> 137.13288 | K19: =Schedules!K26 -> 171.4161 | ... V19: =Schedules!V26 -> 830.44106 | X19: =_xlfn.RRI($V$8-$N$8,N19,V19) -> 0.12621938 | Y19: =_xlfn.RRI($V$8-$Q$8,Q19,V19) -> 0.09755356 | Z19: =_xlfn.RRI($V$8-$S$8,S19,V19) -> 0.076469956
B20: =Schedules!B29 -> Power & Fuel Cost | D20: =Schedules!D31 -> 26 | E20: =Schedules!E31 -> 100 | F20: =Schedules!F31 -> 154 | G20: =Schedules!G31 -> 141 | H20: =Schedules!H31 -> 180 | I20: =Schedules!I31 -> 207.06 | J20: =Schedules!J31 -> 252.6132 | K20: =Schedules!K31 -> 315.7665 | ... V20: =Schedules!V31 -> 1529.7598 | X20: =_xlfn.RRI($V$8-$N$8,N20,V20) -> 0.12621938 | Y20: =_xlfn.RRI($V$8-$Q$8,Q20,V20) -> 0.09755356 | Z20: =_xlfn.RRI($V$8-$S$8,S20,V20) -> 0.076469956
B21: =Schedules!B34 -> Other Operating Expenses | D21: =Schedules!D36 -> 44 | E21: =Schedules!E36 -> 63 | F21: =Schedules!F36 -> 80 | G21: =Schedules!G36 -> 86 | H21: =Schedules!H36 -> 94 | I21: =Schedules!I36 -> 121.278 | J21: =Schedules!J36 -> 147.95916 | K21: =Schedules!K36 -> 184.94895 | ... V21: =Schedules!V36 -> 896.00219 | X21: =_xlfn.RRI($V$8-$N$8,N21,V21) -> 0.12621938 | Y21: =_xlfn.RRI($V$8-$Q$8,Q21,V21) -> 0.09755356 | Z21: =_xlfn.RRI($V$8-$S$8,S21,V21) -> 0.076469956
B22: =Schedules!B39 -> Other SG&A Expenses | D22: =Schedules!D41 -> 71.2 | E22: =Schedules!E41 -> 64.8 | F22: =Schedules!F41 -> 80.6 | G22: =Schedules!G41 -> 79.3 | H22: =Schedules!H41 -> 113.6 | I22: =Schedules!I41 -> 121.278 | J22: =Schedules!J41 -> 147.95916 | K22: =Schedules!K41 -> 184.94895 | ... V22: =Schedules!V41 -> 896.00219 | X22: =_xlfn.RRI($V$8-$N$8,N22,V22) -> 0.12621938 | Y22: =_xlfn.RRI($V$8-$Q$8,Q22,V22) -> 0.09755356 | Z22: =_xlfn.RRI($V$8-$S$8,S22,V22) -> 0.076469956
B23: Total SG&A Expenses | D23: =SUM(D19:D22) -> 182.2 | E23: =SUM(E19:E22) -> 279.8 | F23: =SUM(F19:F22) -> 383.6 | G23: =SUM(G19:G22) -> 387.3 | H23: =SUM(H19:H22) -> 485.6 | I23: =SUM(I19:I22) -> 562.02 | J23: =SUM(J19:J22) -> 685.6644 | K23: =SUM(K19:K22) -> 857.0805 | ... V23: =SUM(V19:V22) -> 4152.2053
B24: EBITDA | D24: =D14-D23 -> 261.8 | E24: =E14-E23 -> 510.2 | F24: =F14-F23 -> 689.4 | G24: =G14-G23 -> 480.7 | H24: =H14-H23 -> 711.4 | I24: =I14-I23 -> 769.08 | J24: =J14-J23 -> 959.93016 | K24: =K14-K23 -> 1199.9127 | ... V24: =V14-V23 -> 7211.725 | X24: =_xlfn.RRI($V$8-$N$8,N24,V24) -> 0.14938358 | Y24: =_xlfn.RRI($V$8-$Q$8,Q24,V24) -> 0.1043291 | Z24: =_xlfn.RRI($V$8-$S$8,S24,V24) -> 0.087568367
B26: Ebitda Margin | D26: =D24/D12 -> 0.31580217 | E26: =E24/E12 -> 0.32894907 | F26: =F24/F12 -> 0.31508227 | G26: =G24/G12 -> 0.24919647 | H26: =H24/H12 -> 0.27898039 | I26: =I24/I12 -> 0.26 | J26: =J24/J12 -> 0.266 | K26: =K24/K12 -> 0.266 | ... V26: =V24/V12 -> 0.33
B28: Less: Depreciation & Amortization
B29: Depreciation | D29: =' Income Statement'!D26*-1 -> 70.77 | E29: =' Income Statement'!E26*-1 -> 82.67 | F29: =' Income Statement'!F26*-1 -> 105.72 | G29: =' Income Statement'!G26*-1 -> 120.33 | H29: =' Income Statement'!H26*-1 -> 129.33 | I29: =Schedules!I72 -> 161.47286 | J29: =Schedules!J72 -> 204.33 | K29: =Schedules!K72 -> 257.90143 | L29: =Schedules!L72 -> 322.18714 | M29: =Schedules!M72 -> 397.18714 | N29: =Schedules!N72 -> 482.90143 | O29: =Schedules!O72 -> 579.33 | P29: =Schedules!P72 -> 686.47286 | ... V29: =Schedules!V72 -> 1425.5758 | X29: =_xlfn.RRI($V$8-$N$8,N29,V29) -> 0.14489716 | Y29: =_xlfn.RRI($V$8-$Q$8,Q29,V29) -> 0.1230736 | Z29: =_xlfn.RRI($V$8-$S$8,S29,V29) -> 0.11287599
B30: Amortization | D30: =' Income Statement'!D27*-1 -> 3.23 | E30: =' Income Statement'!E27*-1 -> 3.23 | F30: =' Income Statement'!F27*-1 -> 3.23 | G30: =' Income Statement'!G27*-1 -> 3.23 | H30: =' Income Statement'!H27*-1 -> 3.23 | I30: =Schedules!I77 -> 3.23 | J30: =Schedules!J77 -> 3.23 | K30: =Schedules!K77 -> 3.23 | L30: =Schedules!L77 -> 3.23 | M30: =Schedules!M77 -> 3.23 | N30: =Schedules!N77 -> 3.23 | O30: =Schedules!O77 -> 0 | P30: =Schedules!P77 -> 0 | ... V30: =Schedules!V77 -> 0
